class AppError extends Error {
    constructor(message, statusCode) {
        super(message)
        this.statusCode = statusCode
        this.status = `${statusCode}`.startsWith('4') ? 'fail' : 'error'
        this.isOperational = true

        Error.captureStackTrace(this, this.constructor)
    }
}

class ValidationError extends AppError {
    constructor(message) {
        super(message, 400)
        this.name = 'ValidationError'
    }
}

class AuthenticationError extends AppError {
    constructor(message) {
        super(message, 401)
        this.name = 'AuthenticationError'
    }
}

class AuthorizationError extends AppError {
    constructor(message) {
        super(message, 403)
        this.name = 'AuthorizationError'
    }
}

class NotFoundError extends AppError {
    constructor(message) {
        super(message, 404)
        this.name = 'NotFoundError'
    }
}

const errorHandler = (err, req, res, next) => {
    err.statusCode = err.statusCode || 500
    err.status = err.status || 'error'

    if (process.env.NODE_ENV === 'development') {
        res.status(err.statusCode).json({
            status: err.status,
            error: err,
            message: err.message,
            stack: err.stack
        })
    } else {
        // Production mode
        if (err.isOperational) {
            res.status(err.statusCode).json({
                status: err.status,
                message: err.message
            })
        } else {
            // Programming or unknown errors
            console.error('ERROR ðŸ’¥', err)
            res.status(500).json({
                status: 'error',
                message: 'Something went wrong!'
            })
        }
    }
}

const catchAsync = fn => {
    return (req, res, next) => {
        fn(req, res, next).catch(next)
    }
}

module.exports = {
    AppError,
    ValidationError,
    AuthenticationError,
    AuthorizationError,
    NotFoundError,
    errorHandler,
    catchAsync
} 